2025-02-14 11:28:28 - __main__ - INFO - Starting FashionDataset test
2025-02-14 11:28:28 - __main__ - INFO - Initializing FashionDataset in train mode
2025-02-14 11:28:28 - __main__ - INFO - Configuration: img_size=(224, 224), use_heatmaps=True, augment_heatmaps=False, cache_data=False
2025-02-14 11:28:28 - __main__ - INFO - Loading metadata from: data/processed/metadata.csv
2025-02-14 11:28:28 - __main__ - INFO - Metadata loaded successfully in 0.55 seconds
2025-02-14 11:28:28 - __main__ - INFO - Metadata shape: (289212, 3)
2025-02-14 11:28:28 - __main__ - INFO - Loaded metadata with 289212 entries
2025-02-14 11:28:28 - __main__ - INFO - Using 2 attribute columns: ['attr1', 'attr2']
2025-02-14 11:28:28 - __main__ - INFO - Using 2 context columns: ['context1', 'context2']
2025-02-14 11:28:28 - __main__ - INFO - Setting up image transformations...
2025-02-14 11:28:28 - __main__ - INFO - Starting dataset validation...
2025-02-14 11:28:28 - __main__ - ERROR - Failed to initialize dataset: 'image_path'
Traceback (most recent call last):
  File "X:\dissertation\StyleSyncProject\fyp\Lib\site-packages\pandas\core\indexes\base.py", line 3805, in get_loc
    return self._engine.get_loc(casted_key)
           ^^^^^^^^^^^^^^^^^^^^^^^^^^^^^^^^
  File "index.pyx", line 167, in pandas._libs.index.IndexEngine.get_loc
  File "index.pyx", line 196, in pandas._libs.index.IndexEngine.get_loc
  File "pandas\\_libs\\hashtable_class_helper.pxi", line 7081, in pandas._libs.hashtable.PyObjectHashTable.get_item
  File "pandas\\_libs\\hashtable_class_helper.pxi", line 7089, in pandas._libs.hashtable.PyObjectHashTable.get_item
KeyError: 'image_path'

The above exception was the direct cause of the following exception:

Traceback (most recent call last):
  File "x:\dissertation\StyleSyncProject\utils\fashion_dataset.py", line 87, in __init__
    self._validate_dataset_structure()
  File "x:\dissertation\StyleSyncProject\utils\fashion_dataset.py", line 141, in _validate_dataset_structure
    img_path = os.path.join(self.cropped_images_dir, row['image_path'])
                                                     ~~~^^^^^^^^^^^^^^
  File "X:\dissertation\StyleSyncProject\fyp\Lib\site-packages\pandas\core\series.py", line 1121, in __getitem__
    return self._get_value(key)
           ^^^^^^^^^^^^^^^^^^^^
  File "X:\dissertation\StyleSyncProject\fyp\Lib\site-packages\pandas\core\series.py", line 1237, in _get_value
    loc = self.index.get_loc(label)
          ^^^^^^^^^^^^^^^^^^^^^^^^^
  File "X:\dissertation\StyleSyncProject\fyp\Lib\site-packages\pandas\core\indexes\base.py", line 3812, in get_loc
    raise KeyError(key) from err
KeyError: 'image_path'
2025-02-14 11:28:28 - __main__ - ERROR - FashionDataset test failed
Traceback (most recent call last):
  File "X:\dissertation\StyleSyncProject\fyp\Lib\site-packages\pandas\core\indexes\base.py", line 3805, in get_loc
    return self._engine.get_loc(casted_key)
           ^^^^^^^^^^^^^^^^^^^^^^^^^^^^^^^^
  File "index.pyx", line 167, in pandas._libs.index.IndexEngine.get_loc
  File "index.pyx", line 196, in pandas._libs.index.IndexEngine.get_loc
  File "pandas\\_libs\\hashtable_class_helper.pxi", line 7081, in pandas._libs.hashtable.PyObjectHashTable.get_item
  File "pandas\\_libs\\hashtable_class_helper.pxi", line 7089, in pandas._libs.hashtable.PyObjectHashTable.get_item
KeyError: 'image_path'

The above exception was the direct cause of the following exception:

Traceback (most recent call last):
  File "x:\dissertation\StyleSyncProject\utils\fashion_dataset.py", line 285, in <module>
    dataset = FashionDataset(
              ^^^^^^^^^^^^^^^
  File "x:\dissertation\StyleSyncProject\utils\fashion_dataset.py", line 87, in __init__
    self._validate_dataset_structure()
  File "x:\dissertation\StyleSyncProject\utils\fashion_dataset.py", line 141, in _validate_dataset_structure
    img_path = os.path.join(self.cropped_images_dir, row['image_path'])
                                                     ~~~^^^^^^^^^^^^^^
  File "X:\dissertation\StyleSyncProject\fyp\Lib\site-packages\pandas\core\series.py", line 1121, in __getitem__
    return self._get_value(key)
           ^^^^^^^^^^^^^^^^^^^^
  File "X:\dissertation\StyleSyncProject\fyp\Lib\site-packages\pandas\core\series.py", line 1237, in _get_value
    loc = self.index.get_loc(label)
          ^^^^^^^^^^^^^^^^^^^^^^^^^
  File "X:\dissertation\StyleSyncProject\fyp\Lib\site-packages\pandas\core\indexes\base.py", line 3812, in get_loc
    raise KeyError(key) from err
KeyError: 'image_path'
2025-02-15 00:59:15 - __main__ - INFO - Starting FashionDataset test
2025-02-15 00:59:15 - __main__ - INFO - Initializing FashionDataset in train mode
2025-02-15 00:59:15 - __main__ - INFO - Configuration: img_size=(224, 224), use_heatmaps=True, augment_heatmaps=False, cache_data=False
2025-02-15 00:59:15 - __main__ - INFO - Loading metadata from: data/processed/metadata.csv
2025-02-15 00:59:16 - __main__ - INFO - Metadata loaded successfully in 0.70 seconds
2025-02-15 00:59:16 - __main__ - INFO - Metadata shape: (289212, 3)
2025-02-15 00:59:16 - __main__ - INFO - Loaded metadata with 289212 entries
2025-02-15 00:59:16 - __main__ - INFO - Using 2 attribute columns: ['attr1', 'attr2']
2025-02-15 00:59:16 - __main__ - INFO - Using 2 context columns: ['context1', 'context2']
2025-02-15 00:59:16 - __main__ - INFO - Setting up image transformations...
2025-02-15 00:59:16 - __main__ - INFO - Starting dataset validation...
2025-02-15 00:59:16 - __main__ - ERROR - Failed to initialize dataset: 'image_path'
Traceback (most recent call last):
  File "X:\dissertation\StyleSyncProject\fyp\Lib\site-packages\pandas\core\indexes\base.py", line 3805, in get_loc
    return self._engine.get_loc(casted_key)
           ^^^^^^^^^^^^^^^^^^^^^^^^^^^^^^^^
  File "index.pyx", line 167, in pandas._libs.index.IndexEngine.get_loc
  File "index.pyx", line 196, in pandas._libs.index.IndexEngine.get_loc
  File "pandas\\_libs\\hashtable_class_helper.pxi", line 7081, in pandas._libs.hashtable.PyObjectHashTable.get_item
  File "pandas\\_libs\\hashtable_class_helper.pxi", line 7089, in pandas._libs.hashtable.PyObjectHashTable.get_item
KeyError: 'image_path'

The above exception was the direct cause of the following exception:

Traceback (most recent call last):
  File "x:\dissertation\StyleSyncProject\utils\fashion_dataset.py", line 87, in __init__
    self._validate_dataset_structure()
  File "x:\dissertation\StyleSyncProject\utils\fashion_dataset.py", line 141, in _validate_dataset_structure
    img_path = os.path.join(self.cropped_images_dir, row['image_path'])
                                                     ~~~^^^^^^^^^^^^^^
  File "X:\dissertation\StyleSyncProject\fyp\Lib\site-packages\pandas\core\series.py", line 1121, in __getitem__
    return self._get_value(key)
           ^^^^^^^^^^^^^^^^^^^^
  File "X:\dissertation\StyleSyncProject\fyp\Lib\site-packages\pandas\core\series.py", line 1237, in _get_value
    loc = self.index.get_loc(label)
          ^^^^^^^^^^^^^^^^^^^^^^^^^
  File "X:\dissertation\StyleSyncProject\fyp\Lib\site-packages\pandas\core\indexes\base.py", line 3812, in get_loc
    raise KeyError(key) from err
KeyError: 'image_path'
2025-02-15 00:59:16 - __main__ - ERROR - FashionDataset test failed
Traceback (most recent call last):
  File "X:\dissertation\StyleSyncProject\fyp\Lib\site-packages\pandas\core\indexes\base.py", line 3805, in get_loc
    return self._engine.get_loc(casted_key)
           ^^^^^^^^^^^^^^^^^^^^^^^^^^^^^^^^
  File "index.pyx", line 167, in pandas._libs.index.IndexEngine.get_loc
  File "index.pyx", line 196, in pandas._libs.index.IndexEngine.get_loc
  File "pandas\\_libs\\hashtable_class_helper.pxi", line 7081, in pandas._libs.hashtable.PyObjectHashTable.get_item
  File "pandas\\_libs\\hashtable_class_helper.pxi", line 7089, in pandas._libs.hashtable.PyObjectHashTable.get_item
KeyError: 'image_path'

The above exception was the direct cause of the following exception:

Traceback (most recent call last):
  File "x:\dissertation\StyleSyncProject\utils\fashion_dataset.py", line 285, in <module>
    dataset = FashionDataset(
              ^^^^^^^^^^^^^^^
  File "x:\dissertation\StyleSyncProject\utils\fashion_dataset.py", line 87, in __init__
    self._validate_dataset_structure()
  File "x:\dissertation\StyleSyncProject\utils\fashion_dataset.py", line 141, in _validate_dataset_structure
    img_path = os.path.join(self.cropped_images_dir, row['image_path'])
                                                     ~~~^^^^^^^^^^^^^^
  File "X:\dissertation\StyleSyncProject\fyp\Lib\site-packages\pandas\core\series.py", line 1121, in __getitem__
    return self._get_value(key)
           ^^^^^^^^^^^^^^^^^^^^
  File "X:\dissertation\StyleSyncProject\fyp\Lib\site-packages\pandas\core\series.py", line 1237, in _get_value
    loc = self.index.get_loc(label)
          ^^^^^^^^^^^^^^^^^^^^^^^^^
  File "X:\dissertation\StyleSyncProject\fyp\Lib\site-packages\pandas\core\indexes\base.py", line 3812, in get_loc
    raise KeyError(key) from err
KeyError: 'image_path'
2025-02-15 01:03:54 - __main__ - INFO - Starting FashionDataset test
2025-02-15 01:03:54 - __main__ - INFO - Initializing FashionDataset in train mode
2025-02-15 01:03:54 - __main__ - INFO - Configuration: img_size=(224, 224), use_heatmaps=True, augment_heatmaps=False, cache_data=False
2025-02-15 01:03:54 - __main__ - INFO - Loading metadata from: data/processed/metadata.csv
2025-02-15 01:03:55 - __main__ - INFO - Metadata loaded successfully in 0.52 seconds
2025-02-15 01:03:55 - __main__ - INFO - Metadata shape: (289212, 3)
2025-02-15 01:03:55 - __main__ - INFO - Loaded metadata with 289212 entries
2025-02-15 01:03:55 - __main__ - INFO - Using 2 attribute columns: ['attr1', 'attr2']
2025-02-15 01:03:55 - __main__ - INFO - Using 2 context columns: ['context1', 'context2']
2025-02-15 01:03:55 - __main__ - INFO - Setting up image transformations...
2025-02-15 01:03:55 - __main__ - INFO - Starting dataset validation...
2025-02-15 01:39:13 - __main__ - INFO - Dataset validation completed in 2118.10 seconds
2025-02-15 01:39:13 - __main__ - WARNING - Found 0 missing images
2025-02-15 01:39:13 - __main__ - WARNING - Found 289212 missing heatmaps
2025-02-15 01:39:13 - __main__ - WARNING - Found 0 corrupted files
2025-02-15 01:39:13 - __main__ - INFO - Dataset initialization completed in 2118.64 seconds
2025-02-15 01:39:13 - __main__ - INFO - Dataset size: 289212
2025-02-15 01:39:13 - __main__ - ERROR - Error loading item 0: [Errno 2] No such file or directory: 'x:\\dissertation\\StyleSyncProject\\data\\processed\\cropped_images\\1981_Graphic_Ringer_Tee\\img_00000001.npy'
Traceback (most recent call last):
  File "x:\dissertation\StyleSyncProject\utils\fashion_dataset.py", line 248, in __getitem__
    heatmap = np.load(heatmap_path)
              ^^^^^^^^^^^^^^^^^^^^^
  File "X:\dissertation\StyleSyncProject\fyp\Lib\site-packages\numpy\lib\_npyio_impl.py", line 455, in load
    fid = stack.enter_context(open(os.fspath(file), "rb"))
                              ^^^^^^^^^^^^^^^^^^^^^^^^^^^
FileNotFoundError: [Errno 2] No such file or directory: 'x:\\dissertation\\StyleSyncProject\\data\\processed\\cropped_images\\1981_Graphic_Ringer_Tee\\img_00000001.npy'
2025-02-15 01:39:13 - __main__ - ERROR - FashionDataset test failed
Traceback (most recent call last):
  File "x:\dissertation\StyleSyncProject\utils\fashion_dataset.py", line 298, in <module>
    sample = dataset[0]
             ~~~~~~~^^^
  File "x:\dissertation\StyleSyncProject\utils\fashion_dataset.py", line 248, in __getitem__
    heatmap = np.load(heatmap_path)
              ^^^^^^^^^^^^^^^^^^^^^
  File "X:\dissertation\StyleSyncProject\fyp\Lib\site-packages\numpy\lib\_npyio_impl.py", line 455, in load
    fid = stack.enter_context(open(os.fspath(file), "rb"))
                              ^^^^^^^^^^^^^^^^^^^^^^^^^^^
FileNotFoundError: [Errno 2] No such file or directory: 'x:\\dissertation\\StyleSyncProject\\data\\processed\\cropped_images\\1981_Graphic_Ringer_Tee\\img_00000001.npy'
2025-02-15 02:45:11 - __main__ - INFO - Starting FashionDataset test
2025-02-15 02:45:11 - __main__ - INFO - Initializing FashionDataset in train mode
2025-02-15 02:45:11 - __main__ - INFO - Configuration: img_size=(224, 224), use_heatmaps=True, augment_heatmaps=False, cache_data=False
2025-02-15 02:45:11 - __main__ - INFO - Loading metadata from: data/processed/metadata.csv
2025-02-15 02:45:12 - __main__ - INFO - Metadata loaded successfully in 0.55 seconds
2025-02-15 02:45:12 - __main__ - INFO - Metadata shape: (289212, 3)
2025-02-15 02:45:12 - __main__ - INFO - Loaded metadata with 289212 entries
2025-02-15 02:45:12 - __main__ - INFO - Using 2 attribute columns: ['attr1', 'attr2']
2025-02-15 02:45:12 - __main__ - INFO - Using 2 context columns: ['context1', 'context2']
2025-02-15 02:45:12 - __main__ - INFO - Setting up image transformations...
2025-02-15 02:45:12 - __main__ - INFO - Starting dataset validation...
2025-02-15 02:48:13 - __main__ - INFO - Starting FashionDataset test
2025-02-15 02:48:13 - __main__ - INFO - Initializing FashionDataset in train mode
2025-02-15 02:48:13 - __main__ - INFO - Configuration: img_size=(224, 224), use_heatmaps=True, augment_heatmaps=False, cache_data=False
2025-02-15 02:48:13 - __main__ - INFO - Loading metadata from: data/processed/metadata.csv
2025-02-15 02:48:14 - __main__ - INFO - Metadata loaded successfully in 0.51 seconds
2025-02-15 02:48:14 - __main__ - INFO - Metadata shape: (289212, 3)
2025-02-15 02:48:14 - __main__ - INFO - Loaded metadata with 289212 entries
2025-02-15 02:48:14 - __main__ - INFO - Using 2 attribute columns: ['attr1', 'attr2']
2025-02-15 02:48:14 - __main__ - INFO - Using 2 context columns: ['context1', 'context2']
2025-02-15 02:48:14 - __main__ - INFO - Setting up image transformations...
2025-02-15 02:48:14 - __main__ - INFO - Starting dataset validation...
2025-02-15 03:22:23 - __main__ - INFO - Dataset validation completed in 2049.16 seconds
2025-02-15 03:22:23 - __main__ - WARNING - Found 0 missing images
2025-02-15 03:22:23 - __main__ - WARNING - Found 289212 missing heatmaps
2025-02-15 03:22:23 - __main__ - WARNING - Found 0 corrupted files
2025-02-15 03:22:23 - __main__ - INFO - Dataset initialization completed in 2049.69 seconds
2025-02-15 03:22:23 - __main__ - INFO - Dataset size: 289212
2025-02-15 03:22:23 - __main__ - ERROR - Error loading item 0: [Errno 2] No such file or directory: 'x:\\dissertation\\StyleSyncProject\\data\\processed\\cropped_images\\1981_Graphic_Ringer_Tee\\img_00000001.npy'
Traceback (most recent call last):
  File "x:\dissertation\StyleSyncProject\utils\fashion_dataset.py", line 248, in __getitem__
    heatmap = np.load(heatmap_path)
              ^^^^^^^^^^^^^^^^^^^^^
  File "X:\dissertation\StyleSyncProject\fyp\Lib\site-packages\numpy\lib\_npyio_impl.py", line 455, in load
    fid = stack.enter_context(open(os.fspath(file), "rb"))
                              ^^^^^^^^^^^^^^^^^^^^^^^^^^^
FileNotFoundError: [Errno 2] No such file or directory: 'x:\\dissertation\\StyleSyncProject\\data\\processed\\cropped_images\\1981_Graphic_Ringer_Tee\\img_00000001.npy'
2025-02-15 03:22:23 - __main__ - ERROR - FashionDataset test failed
Traceback (most recent call last):
  File "x:\dissertation\StyleSyncProject\utils\fashion_dataset.py", line 298, in <module>
    sample = dataset[0]
             ~~~~~~~^^^
  File "x:\dissertation\StyleSyncProject\utils\fashion_dataset.py", line 248, in __getitem__
    heatmap = np.load(heatmap_path)
              ^^^^^^^^^^^^^^^^^^^^^
  File "X:\dissertation\StyleSyncProject\fyp\Lib\site-packages\numpy\lib\_npyio_impl.py", line 455, in load
    fid = stack.enter_context(open(os.fspath(file), "rb"))
                              ^^^^^^^^^^^^^^^^^^^^^^^^^^^
FileNotFoundError: [Errno 2] No such file or directory: 'x:\\dissertation\\StyleSyncProject\\data\\processed\\cropped_images\\1981_Graphic_Ringer_Tee\\img_00000001.npy'
2025-02-15 04:16:59 - __main__ - INFO - Starting FashionDataset test
2025-02-15 04:16:59 - __main__ - INFO - Initializing FashionDataset in train mode
2025-02-15 04:16:59 - __main__ - INFO - Configuration: img_size=(224, 224), use_heatmaps=True, augment_heatmaps=False, cache_data=False
2025-02-15 04:16:59 - __main__ - INFO - Loading metadata from: data/processed/metadata.csv
2025-02-15 04:17:00 - __main__ - INFO - Metadata loaded successfully in 0.78 seconds
2025-02-15 04:17:00 - __main__ - INFO - Metadata shape: (289212, 3)
2025-02-15 04:17:00 - __main__ - INFO - Loaded metadata with 289212 entries
2025-02-15 04:17:00 - __main__ - INFO - Using 2 attribute columns: ['attr1', 'attr2']
2025-02-15 04:17:00 - __main__ - INFO - Using 2 context columns: ['context1', 'context2']
2025-02-15 04:17:00 - __main__ - INFO - Setting up image transformations...
2025-02-15 04:17:00 - __main__ - INFO - Starting dataset validation...
2025-02-15 04:56:14 - __main__ - INFO - Dataset validation completed in 2354.34 seconds
2025-02-15 04:56:14 - __main__ - INFO - All files validated successfully
2025-02-15 04:56:14 - __main__ - INFO - Dataset initialization completed in 2355.15 seconds
2025-02-15 04:56:14 - __main__ - INFO - Dataset size: 289212
2025-02-15 04:56:14 - __main__ - ERROR - Error loading item 0: "None of [Index(['attr1', 'attr2'], dtype='object')] are in the [index]"
Traceback (most recent call last):
  File "x:\dissertation\StyleSyncProject\utils\fashion_dataset.py", line 254, in __getitem__
    attributes = torch.tensor(row[self.attribute_cols].values.astype(np.float32))
                              ~~~^^^^^^^^^^^^^^^^^^^^^
  File "X:\dissertation\StyleSyncProject\fyp\Lib\site-packages\pandas\core\series.py", line 1153, in __getitem__
    return self._get_with(key)
           ^^^^^^^^^^^^^^^^^^^
  File "X:\dissertation\StyleSyncProject\fyp\Lib\site-packages\pandas\core\series.py", line 1194, in _get_with
    return self.loc[key]
           ~~~~~~~~^^^^^
  File "X:\dissertation\StyleSyncProject\fyp\Lib\site-packages\pandas\core\indexing.py", line 1191, in __getitem__
    return self._getitem_axis(maybe_callable, axis=axis)
           ^^^^^^^^^^^^^^^^^^^^^^^^^^^^^^^^^^^^^^^^^^^^^
  File "X:\dissertation\StyleSyncProject\fyp\Lib\site-packages\pandas\core\indexing.py", line 1420, in _getitem_axis
    return self._getitem_iterable(key, axis=axis)
           ^^^^^^^^^^^^^^^^^^^^^^^^^^^^^^^^^^^^^^
  File "X:\dissertation\StyleSyncProject\fyp\Lib\site-packages\pandas\core\indexing.py", line 1360, in _getitem_iterable
    keyarr, indexer = self._get_listlike_indexer(key, axis)
                      ^^^^^^^^^^^^^^^^^^^^^^^^^^^^^^^^^^^^^
  File "X:\dissertation\StyleSyncProject\fyp\Lib\site-packages\pandas\core\indexing.py", line 1558, in _get_listlike_indexer
    keyarr, indexer = ax._get_indexer_strict(key, axis_name)
                      ^^^^^^^^^^^^^^^^^^^^^^^^^^^^^^^^^^^^^^
  File "X:\dissertation\StyleSyncProject\fyp\Lib\site-packages\pandas\core\indexes\base.py", line 6200, in _get_indexer_strict
    self._raise_if_missing(keyarr, indexer, axis_name)
  File "X:\dissertation\StyleSyncProject\fyp\Lib\site-packages\pandas\core\indexes\base.py", line 6249, in _raise_if_missing
    raise KeyError(f"None of [{key}] are in the [{axis_name}]")
KeyError: "None of [Index(['attr1', 'attr2'], dtype='object')] are in the [index]"
2025-02-15 04:56:14 - __main__ - ERROR - FashionDataset test failed
Traceback (most recent call last):
  File "x:\dissertation\StyleSyncProject\utils\fashion_dataset.py", line 301, in <module>
    sample = dataset[0]
             ~~~~~~~^^^
  File "x:\dissertation\StyleSyncProject\utils\fashion_dataset.py", line 254, in __getitem__
    attributes = torch.tensor(row[self.attribute_cols].values.astype(np.float32))
                              ~~~^^^^^^^^^^^^^^^^^^^^^
  File "X:\dissertation\StyleSyncProject\fyp\Lib\site-packages\pandas\core\series.py", line 1153, in __getitem__
    return self._get_with(key)
           ^^^^^^^^^^^^^^^^^^^
  File "X:\dissertation\StyleSyncProject\fyp\Lib\site-packages\pandas\core\series.py", line 1194, in _get_with
    return self.loc[key]
           ~~~~~~~~^^^^^
  File "X:\dissertation\StyleSyncProject\fyp\Lib\site-packages\pandas\core\indexing.py", line 1191, in __getitem__
    return self._getitem_axis(maybe_callable, axis=axis)
           ^^^^^^^^^^^^^^^^^^^^^^^^^^^^^^^^^^^^^^^^^^^^^
  File "X:\dissertation\StyleSyncProject\fyp\Lib\site-packages\pandas\core\indexing.py", line 1420, in _getitem_axis
    return self._getitem_iterable(key, axis=axis)
           ^^^^^^^^^^^^^^^^^^^^^^^^^^^^^^^^^^^^^^
  File "X:\dissertation\StyleSyncProject\fyp\Lib\site-packages\pandas\core\indexing.py", line 1360, in _getitem_iterable
    keyarr, indexer = self._get_listlike_indexer(key, axis)
                      ^^^^^^^^^^^^^^^^^^^^^^^^^^^^^^^^^^^^^
  File "X:\dissertation\StyleSyncProject\fyp\Lib\site-packages\pandas\core\indexing.py", line 1558, in _get_listlike_indexer
    keyarr, indexer = ax._get_indexer_strict(key, axis_name)
                      ^^^^^^^^^^^^^^^^^^^^^^^^^^^^^^^^^^^^^^
  File "X:\dissertation\StyleSyncProject\fyp\Lib\site-packages\pandas\core\indexes\base.py", line 6200, in _get_indexer_strict
    self._raise_if_missing(keyarr, indexer, axis_name)
  File "X:\dissertation\StyleSyncProject\fyp\Lib\site-packages\pandas\core\indexes\base.py", line 6249, in _raise_if_missing
    raise KeyError(f"None of [{key}] are in the [{axis_name}]")
KeyError: "None of [Index(['attr1', 'attr2'], dtype='object')] are in the [index]"
